Workbook

Sheet Schedule
O1: today — Jul 10
A2: Project Schedule and Timeline (June to December 2026) | K2: Jun | O2: Jul | S2: Aug | W2: Sep | AA2: Oct | AE2: Nov | AI2: Dec
A3: Reporting date: July 10, 2026. Milestone dates follow the signed Schedule of Deliverables. | K3: 1 | L3: 2 | M3: 3 | N3: 4 | O3: 1 | P3: 2 | Q3: 3 | R3: 4 | S3: 1 | T3: 2 | U3: 3 | V3: 4 | W3: 1 | X3: 2 | Y3: 3 | Z3: 4 | AA3: 1 | AB3: 2 | AC3: 3 | AD3: 4 | AE3: 1 | AF3: 2 | AG3: 3 | AH3: 4 | AI3: 1 | AJ3: 2 | AK3: 3 | AL3: 4
A4: Phase | B4: ID | C4: Task | D4: Owner | E4: Deliverable | F4: Depends on | G4: Start | H4: End | I4: Status | J4: % Complete
A5: WRITING | K5: =IF(AND(ISNUMBER($G5), ISNUMBER($H5), $G5<=Helper!L$2, $H5>=Helper!L$1), 1, "") | L5: =IF(AND(ISNUMBER($G5), ISNUMBER($H5), $G5<=Helper!M$2, $H5>=Helper!M$1), 1, "") | M5: =IF(AND(ISNUMBER($G5), ISNUMBER($H5), $G5<=Helper!N$2, $H5>=Helper!N$1), 1, "") | N5: =IF(AND(ISNUMBER($G5), ISNUMBER($H5), $G5<=Helper!O$2, $H5>=Helper!O$1), 1, "") | O5: =IF(AND(ISNUMBER($G5), ISNUMBER($H5), $G5<=Helper!P$2, $H5>=Helper!P$1), 1, "") | P5: =IF(AND(ISNUMBER($G5), ISNUMBER($H5), $G5<=Helper!Q$2, $H5>=Helper!Q$1), 1, "") | Q5: =IF(AND(ISNUMBER($G5), ISNUMBER($H5), $G5<=Helper!R$2, $H5>=Helper!R$1), 1, "") | R5: =IF(AND(ISNUMBER($G5), ISNUMBER($H5), $G5<=Helper!S$2, $H5>=Helper!S$1), 1, "") | ... AL5: =IF(AND(ISNUMBER($G5), ISNUMBER($H5), $G5<=Helper!AM$2, $H5>=Helper!AM$1), 1, "")
B6: W1 | C6: Ch. 2 — Review of Related Literature | D6: JD | E6: Chapter 2 draft + verified reference catalog | F6: — | G6: 46174 | H6: 46206 | I6: Done | J6: 1 | K6: =IF(AND(ISNUMBER($G6), ISNUMBER($H6), $G6<=Helper!L$2, $H6>=Helper!L$1), 1, "") -> 1 | L6: =IF(AND(ISNUMBER($G6), ISNUMBER($H6), $G6<=Helper!M$2, $H6>=Helper!M$1), 1, "") -> 1 | M6: =IF(AND(ISNUMBER($G6), ISNUMBER($H6), $G6<=Helper!N$2, $H6>=Helper!N$1), 1, "") -> 1 | N6: =IF(AND(ISNUMBER($G6), ISNUMBER($H6), $G6<=Helper!O$2, $H6>=Helper!O$1), 1, "") -> 1 | O6: =IF(AND(ISNUMBER($G6), ISNUMBER($H6), $G6<=Helper!P$2, $H6>=Helper!P$1), 1, "") -> 1 | P6: =IF(AND(ISNUMBER($G6), ISNUMBER($H6), $G6<=Helper!Q$2, $H6>=Helper!Q$1), 1, "") | Q6: =IF(AND(ISNUMBER($G6), ISNUMBER($H6), $G6<=Helper!R$2, $H6>=Helper!R$1), 1, "") | R6: =IF(AND(ISNUMBER($G6), ISNUMBER($H6), $G6<=Helper!S$2, $H6>=Helper!S$1), 1, "") | ... AL6: =IF(AND(ISNUMBER($G6), ISNUMBER($H6), $G6<=Helper!AM$2, $H6>=Helper!AM$1), 1, "")
B7: W2 | C7: Ch. 3 — Technical Background | D7: JD | E7: Chapter 3 draft, 11 equations, 7 figures | F7: W1 | G7: 46181 | H7: 46206 | I7: Done | J7: 1 | K7: =IF(AND(ISNUMBER($G7), ISNUMBER($H7), $G7<=Helper!L$2, $H7>=Helper!L$1), 1, "") | L7: =IF(AND(ISNUMBER($G7), ISNUMBER($H7), $G7<=Helper!M$2, $H7>=Helper!M$1), 1, "") -> 1 | M7: =IF(AND(ISNUMBER($G7), ISNUMBER($H7), $G7<=Helper!N$2, $H7>=Helper!N$1), 1, "") -> 1 | N7: =IF(AND(ISNUMBER($G7), ISNUMBER($H7), $G7<=Helper!O$2, $H7>=Helper!O$1), 1, "") -> 1 | O7: =IF(AND(ISNUMBER($G7), ISNUMBER($H7), $G7<=Helper!P$2, $H7>=Helper!P$1), 1, "") -> 1 | P7: =IF(AND(ISNUMBER($G7), ISNUMBER($H7), $G7<=Helper!Q$2, $H7>=Helper!Q$1), 1, "") | Q7: =IF(AND(ISNUMBER($G7), ISNUMBER($H7), $G7<=Helper!R$2, $H7>=Helper!R$1), 1, "") | R7: =IF(AND(ISNUMBER($G7), ISNUMBER($H7), $G7<=Helper!S$2, $H7>=Helper!S$1), 1, "") | ... AL7: =IF(AND(ISNUMBER($G7), ISNUMBER($H7), $G7<=Helper!AM$2, $H7>=Helper!AM$1), 1, "")
B8: W3 | C8: Bibliography (APA 7th) | D8: JD | E8: Alphabetized APA 7th reference list | F8: W1 | G8: 46195 | H8: 46206 | I8: Done | J8: 1 | K8: =IF(AND(ISNUMBER($G8), ISNUMBER($H8), $G8<=Helper!L$2, $H8>=Helper!L$1), 1, "") | L8: =IF(AND(ISNUMBER($G8), ISNUMBER($H8), $G8<=Helper!M$2, $H8>=Helper!M$1), 1, "") | M8: =IF(AND(ISNUMBER($G8), ISNUMBER($H8), $G8<=Helper!N$2, $H8>=Helper!N$1), 1, "") | N8: =IF(AND(ISNUMBER($G8), ISNUMBER($H8), $G8<=Helper!O$2, $H8>=Helper!O$1), 1, "") -> 1 | O8: =IF(AND(ISNUMBER($G8), ISNUMBER($H8), $G8<=Helper!P$2, $H8>=Helper!P$1), 1, "") -> 1 | P8: =IF(AND(ISNUMBER($G8), ISNUMBER($H8), $G8<=Helper!Q$2, $H8>=Helper!Q$1), 1, "") | Q8: =IF(AND(ISNUMBER($G8), ISNUMBER($H8), $G8<=Helper!R$2, $H8>=Helper!R$1), 1, "") | R8: =IF(AND(ISNUMBER($G8), ISNUMBER($H8), $G8<=Helper!S$2, $H8>=Helper!S$1), 1, "") | ... AL8: =IF(AND(ISNUMBER($G8), ISNUMBER($H8), $G8<=Helper!AM$2, $H8>=Helper!AM$1), 1, "")
B9: W4 | C9: Research objectives / statement of the problem | D9: Both | E9: Objectives + SOP section | F9: — | G9: 46195 | H9: 46212 | I9: Done | J9: 1 | K9: =IF(AND(ISNUMBER($G9), ISNUMBER($H9), $G9<=Helper!L$2, $H9>=Helper!L$1), 1, "") | L9: =IF(AND(ISNUMBER($G9), ISNUMBER($H9), $G9<=Helper!M$2, $H9>=Helper!M$1), 1, "") | M9: =IF(AND(ISNUMBER($G9), ISNUMBER($H9), $G9<=Helper!N$2, $H9>=Helper!N$1), 1, "") | N9: =IF(AND(ISNUMBER($G9), ISNUMBER($H9), $G9<=Helper!O$2, $H9>=Helper!O$1), 1, "") -> 1 | O9: =IF(AND(ISNUMBER($G9), ISNUMBER($H9), $G9<=Helper!P$2, $H9>=Helper!P$1), 1, "") -> 1 | P9: =IF(AND(ISNUMBER($G9), ISNUMBER($H9), $G9<=Helper!Q$2, $H9>=Helper!Q$1), 1, "") -> 1 | Q9: =IF(AND(ISNUMBER($G9), ISNUMBER($H9), $G9<=Helper!R$2, $H9>=Helper!R$1), 1, "") | R9: =IF(AND(ISNUMBER($G9), ISNUMBER($H9), $G9<=Helper!S$2, $H9>=Helper!S$1), 1, "") | ... AL9: =IF(AND(ISNUMBER($G9), ISNUMBER($H9), $G9<=Helper!AM$2, $H9>=Helper!AM$1), 1, "")
B10: W5 | C10: Ch. 4 — Design and Methodology | D10: MC | E10: Chapter 4 draft, §4.1–4.10 | F10: W2 | G10: 46195 | H10: 46213 | I10: In progress | J10: 0.85 | K10: =IF(AND(ISNUMBER($G10), ISNUMBER($H10), $G10<=Helper!L$2, $H10>=Helper!L$1), 1, "") | L10: =IF(AND(ISNUMBER($G10), ISNUMBER($H10), $G10<=Helper!M$2, $H10>=Helper!M$1), 1, "") | M10: =IF(AND(ISNUMBER($G10), ISNUMBER($H10), $G10<=Helper!N$2, $H10>=Helper!N$1), 1, "") | N10: =IF(AND(ISNUMBER($G10), ISNUMBER($H10), $G10<=Helper!O$2, $H10>=Helper!O$1), 1, "") -> 1 | O10: =IF(AND(ISNUMBER($G10), ISNUMBER($H10), $G10<=Helper!P$2, $H10>=Helper!P$1), 1, "") -> 1 | P10: =IF(AND(ISNUMBER($G10), ISNUMBER($H10), $G10<=Helper!Q$2, $H10>=Helper!Q$1), 1, "") -> 1 | Q10: =IF(AND(ISNUMBER($G10), ISNUMBER($H10), $G10<=Helper!R$2, $H10>=Helper!R$1), 1, "") | R10: =IF(AND(ISNUMBER($G10), ISNUMBER($H10), $G10<=Helper!S$2, $H10>=Helper!S$1), 1, "") | ... AL10: =IF(AND(ISNUMBER($G10), ISNUMBER($H10), $G10<=Helper!AM$2, $H10>=Helper!AM$1), 1, "")
B11: W6 | C11: Appendices (transmittal letter, instrument, SRS) + CV | D11: Both | E11: Appendix set + curricula vitae | F11: W5 | G11: 46211 | H11: 46219 | I11: Planned | J11: 0 | K11: =IF(AND(ISNUMBER($G11), ISNUMBER($H11), $G11<=Helper!L$2, $H11>=Helper!L$1), 1, "") | L11: =IF(AND(ISNUMBER($G11), ISNUMBER($H11), $G11<=Helper!M$2, $H11>=Helper!M$1), 1, "") | M11: =IF(AND(ISNUMBER($G11), ISNUMBER($H11), $G11<=Helper!N$2, $H11>=Helper!N$1), 1, "") | N11: =IF(AND(ISNUMBER($G11), ISNUMBER($H11), $G11<=Helper!O$2, $H11>=Helper!O$1), 1, "") | O11: =IF(AND(ISNUMBER($G11), ISNUMBER($H11), $G11<=Helper!P$2, $H11>=Helper!P$1), 1, "") | P11: =IF(AND(ISNUMBER($G11), ISNUMBER($H11), $G11<=Helper!Q$2, $H11>=Helper!Q$1), 1, "") -> 1 | Q11: =IF(AND(ISNUMBER($G11), ISNUMBER($H11), $G11<=Helper!R$2, $H11>=Helper!R$1), 1, "") -> 1 | R11: =IF(AND(ISNUMBER($G11), ISNUMBER($H11), $G11<=Helper!S$2, $H11>=Helper!S$1), 1, "") | ... AL11: =IF(AND(ISNUMBER($G11), ISNUMBER($H11), $G11<=Helper!AM$2, $H11>=Helper!AM$1), 1, "")
B12: W7 | C12: Ch. 1 — Introduction and Abstract | D12: Both | E12: Chapter 1 + abstract | F12: W4 | G12: 46211 | H12: 46220 | I12: Planned | J12: 0 | K12: =IF(AND(ISNUMBER($G12), ISNUMBER($H12), $G12<=Helper!L$2, $H12>=Helper!L$1), 1, "") | L12: =IF(AND(ISNUMBER($G12), ISNUMBER($H12), $G12<=Helper!M$2, $H12>=Helper!M$1), 1, "") | M12: =IF(AND(ISNUMBER($G12), ISNUMBER($H12), $G12<=Helper!N$2, $H12>=Helper!N$1), 1, "") | N12: =IF(AND(ISNUMBER($G12), ISNUMBER($H12), $G12<=Helper!O$2, $H12>=Helper!O$1), 1, "") | O12: =IF(AND(ISNUMBER($G12), ISNUMBER($H12), $G12<=Helper!P$2, $H12>=Helper!P$1), 1, "") | P12: =IF(AND(ISNUMBER($G12), ISNUMBER($H12), $G12<=Helper!Q$2, $H12>=Helper!Q$1), 1, "") -> 1 | Q12: =IF(AND(ISNUMBER($G12), ISNUMBER($H12), $G12<=Helper!R$2, $H12>=Helper!R$1), 1, "") -> 1 | R12: =IF(AND(ISNUMBER($G12), ISNUMBER($H12), $G12<=Helper!S$2, $H12>=Helper!S$1), 1, "") | ... AL12: =IF(AND(ISNUMBER($G12), ISNUMBER($H12), $G12<=Helper!AM$2, $H12>=Helper!AM$1), 1, "")
B13: W8 | C13: Proposal document draft (Ch. 1–4, refs, appendices, CV) | D13: Both | E13: Compiled proposal document | F13: W6, W7 | G13: 46218 | H13: 46226 | I13: Planned | J13: 0 | K13: =IF(AND(ISNUMBER($G13), ISNUMBER($H13), $G13<=Helper!L$2, $H13>=Helper!L$1), 1, "") | L13: =IF(AND(ISNUMBER($G13), ISNUMBER($H13), $G13<=Helper!M$2, $H13>=Helper!M$1), 1, "") | M13: =IF(AND(ISNUMBER($G13), ISNUMBER($H13), $G13<=Helper!N$2, $H13>=Helper!N$1), 1, "") | N13: =IF(AND(ISNUMBER($G13), ISNUMBER($H13), $G13<=Helper!O$2, $H13>=Helper!O$1), 1, "") | O13: =IF(AND(ISNUMBER($G13), ISNUMBER($H13), $G13<=Helper!P$2, $H13>=Helper!P$1), 1, "") | P13: =IF(AND(ISNUMBER($G13), ISNUMBER($H13), $G13<=Helper!Q$2, $H13>=Helper!Q$1), 1, "") | Q13: =IF(AND(ISNUMBER($G13), ISNUMBER($H13), $G13<=Helper!R$2, $H13>=Helper!R$1), 1, "") -> 1 | R13: =IF(AND(ISNUMBER($G13), ISNUMBER($H13), $G13<=Helper!S$2, $H13>=Helper!S$1), 1, "") -> 1 | ... AL13: =IF(AND(ISNUMBER($G13), ISNUMBER($H13), $G13<=Helper!AM$2, $H13>=Helper!AM$1), 1, "")
B14: W9 | C14: Ch. 5 — Results and Discussion | D14: Both | E14: Chapter 5 draft with evaluation tables | F14: D3.4 | G14: 46266 | H14: 46280 | I14: Planned | J14: 0 | K14: =IF(AND(ISNUMBER($G14), ISNUMBER($H14), $G14<=Helper!L$2, $H14>=Helper!L$1), 1, "") | L14: =IF(AND(ISNUMBER($G14), ISNUMBER($H14), $G14<=Helper!M$2, $H14>=Helper!M$1), 1, "") | M14: =IF(AND(ISNUMBER($G14), ISNUMBER($H14), $G14<=Helper!N$2, $H14>=Helper!N$1), 1, "") | N14: =IF(AND(ISNUMBER($G14), ISNUMBER($H14), $G14<=Helper!O$2, $H14>=Helper!O$1), 1, "") | O14: =IF(AND(ISNUMBER($G14), ISNUMBER($H14), $G14<=Helper!P$2, $H14>=Helper!P$1), 1, "") | P14: =IF(AND(ISNUMBER($G14), ISNUMBER($H14), $G14<=Helper!Q$2, $H14>=Helper!Q$1), 1, "") | Q14: =IF(AND(ISNUMBER($G14), ISNUMBER($H14), $G14<=Helper!R$2, $H14>=Helper!R$1), 1, "") | R14: =IF(AND(ISNUMBER($G14), ISNUMBER($H14), $G14<=Helper!S$2, $H14>=Helper!S$1), 1, "") | ... AL14: =IF(AND(ISNUMBER($G14), ISNUMBER($H14), $G14<=Helper!AM$2, $H14>=Helper!AM$1), 1, "")
B15: W10 | C15: Ch. 6 — Summary, Conclusions, Recommendations | D15: Both | E15: Chapter 6 draft | F15: W9 | G15: 46281 | H15: 46326 | I15: Planned | J15: 0 | K15: =IF(AND(ISNUMBER($G15), ISNUMBER($H15), $G15<=Helper!L$2, $H15>=Helper!L$1), 1, "") | L15: =IF(AND(ISNUMBER($G15), ISNUMBER($H15), $G15<=Helper!M$2, $H15>=Helper!M$1), 1, "") | M15: =IF(AND(ISNUMBER($G15), ISNUMBER($H15), $G15<=Helper!N$2, $H15>=Helper!N$1), 1, "") | N15: =IF(AND(ISNUMBER($G15), ISNUMBER($H15), $G15<=Helper!O$2, $H15>=Helper!O$1), 1, "") | O15: =IF(AND(ISNUMBER($G15), ISNUMBER($H15), $G15<=Helper!P$2, $H15>=Helper!P$1), 1, "") | P15: =IF(AND(ISNUMBER($G15), ISNUMBER($H15), $G15<=Helper!Q$2, $H15>=Helper!Q$1), 1, "") | Q15: =IF(AND(ISNUMBER($G15), ISNUMBER($H15), $G15<=Helper!R$2, $H15>=Helper!R$1), 1, "") | R15: =IF(AND(ISNUMBER($G15), ISNUMBER($H15), $G15<=Helper!S$2, $H15>=Helper!S$1), 1, "") | ... AL15: =IF(AND(ISNUMBER($G15), ISNUMBER($H15), $G15<=Helper!AM$2, $H15>=Helper!AM$1), 1, "")
A16: DEVELOPMENT | K16: =IF(AND(ISNUMBER($G16), ISNUMBER($H16), $G16<=Helper!L$2, $H16>=Helper!L$1), 1, "") | L16: =IF(AND(ISNUMBER($G16), ISNUMBER($H16), $G16<=Helper!M$2, $H16>=Helper!M$1), 1, "") | M16: =IF(AND(ISNUMBER($G16), ISNUMBER($H16), $G16<=Helper!N$2, $H16>=Helper!N$1), 1, "") | N16: =IF(AND(ISNUMBER($G16), ISNUMBER($H16), $G16<=Helper!O$2, $H16>=Helper!O$1), 1, "") | O16: =IF(AND(ISNUMBER($G16), ISNUMBER($H16), $G16<=Helper!P$2, $H16>=Helper!P$1), 1, "") | P16: =IF(AND(ISNUMBER($G16), ISNUMBER($H16), $G16<=Helper!Q$2, $H16>=Helper!Q$1), 1, "") | Q16: =IF(AND(ISNUMBER($G16), ISNUMBER($H16), $G16<=Helper!R$2, $H16>=Helper!R$1), 1, "") | R16: =IF(AND(ISNUMBER($G16), ISNUMBER($H16), $G16<=Helper!S$2, $H16>=Helper!S$1), 1, "") | ... AL16: =IF(AND(ISNUMBER($G16), ISNUMBER($H16), $G16<=Helper!AM$2, $H16>=Helper!AM$1), 1, "")
B17: D1 | C17: Increment 1 | D17: JD | E17: Increment 1 Deliverables | F17: W5 | G17: 46204 | H17: 46234 | I17: Planned | J17: 0 | K17: =IF(AND(ISNUMBER($G17), ISNUMBER($H17), $G17<=Helper!L$2, $H17>=Helper!L$1), 1, "") | L17: =IF(AND(ISNUMBER($G17), ISNUMBER($H17), $G17<=Helper!M$2, $H17>=Helper!M$1), 1, "") | M17: =IF(AND(ISNUMBER($G17), ISNUMBER($H17), $G17<=Helper!N$2, $H17>=Helper!N$1), 1, "") | N17: =IF(AND(ISNUMBER($G17), ISNUMBER($H17), $G17<=Helper!O$2, $H17>=Helper!O$1), 1, "") | O17: =IF(AND(ISNUMBER($G17), ISNUMBER($H17), $G17<=Helper!P$2, $H17>=Helper!P$1), 1, "") -> 1 | P17: =IF(AND(ISNUMBER($G17), ISNUMBER($H17), $G17<=Helper!Q$2, $H17>=Helper!Q$1), 1, "") -> 1 | Q17: =IF(AND(ISNUMBER($G17), ISNUMBER($H17), $G17<=Helper!R$2, $H17>=Helper!R$1), 1, "") -> 1 | R17: =IF(AND(ISNUMBER($G17), ISNUMBER($H17), $G17<=Helper!S$2, $H17>=Helper!S$1), 1, "") -> 1 | ... AL17: =IF(AND(ISNUMBER($G17), ISNUMBER($H17), $G17<=Helper!AM$2, $H17>=Helper!AM$1), 1, "")
B18: D2 | C18: Increment 2 | D18: JD | E18: Increment 2 Deliverables | F18: D1 | G18: 46235 | H18: 46265 | I18: Planned | J18: 0 | K18: =IF(AND(ISNUMBER($G18), ISNUMBER($H18), $G18<=Helper!L$2, $H18>=Helper!L$1), 1, "") | L18: =IF(AND(ISNUMBER($G18), ISNUMBER($H18), $G18<=Helper!M$2, $H18>=Helper!M$1), 1, "") | M18: =IF(AND(ISNUMBER($G18), ISNUMBER($H18), $G18<=Helper!N$2, $H18>=Helper!N$1), 1, "") | N18: =IF(AND(ISNUMBER($G18), ISNUMBER($H18), $G18<=Helper!O$2, $H18>=Helper!O$1), 1, "") | O18: =IF(AND(ISNUMBER($G18), ISNUMBER($H18), $G18<=Helper!P$2, $H18>=Helper!P$1), 1, "") | P18: =IF(AND(ISNUMBER($G18), ISNUMBER($H18), $G18<=Helper!Q$2, $H18>=Helper!Q$1), 1, "") | Q18: =IF(AND(ISNUMBER($G18), ISNUMBER($H18), $G18<=Helper!R$2, $H18>=Helper!R$1), 1, "") | R18: =IF(AND(ISNUMBER($G18), ISNUMBER($H18), $G18<=Helper!S$2, $H18>=Helper!S$1), 1, "") | ... AL18: =IF(AND(ISNUMBER($G18), ISNUMBER($H18), $G18<=Helper!AM$2, $H18>=Helper!AM$1), 1, "")
B19: D3 | C19: Increment 3 | D19: Both | E19: Increment 3 Deliverables | F19: D2 | G19: 46259 | H19: 46280 | I19: Planned | J19: 0 | K19: =IF(AND(ISNUMBER($G19), ISNUMBER($H19), $G19<=Helper!L$2, $H19>=Helper!L$1), 1, "") | L19: =IF(AND(ISNUMBER($G19), ISNUMBER($H19), $G19<=Helper!M$2, $H19>=Helper!M$1), 1, "") | M19: =IF(AND(ISNUMBER($G19), ISNUMBER($H19), $G19<=Helper!N$2, $H19>=Helper!N$1), 1, "") | N19: =IF(AND(ISNUMBER($G19), ISNUMBER($H19), $G19<=Helper!O$2, $H19>=Helper!O$1), 1, "") | O19: =IF(AND(ISNUMBER($G19), ISNUMBER($H19), $G19<=Helper!P$2, $H19>=Helper!P$1), 1, "") | P19: =IF(AND(ISNUMBER($G19), ISNUMBER($H19), $G19<=Helper!Q$2, $H19>=Helper!Q$1), 1, "") | Q19: =IF(AND(ISNUMBER($G19), ISNUMBER($H19), $G19<=Helper!R$2, $H19>=Helper!R$1), 1, "") | R19: =IF(AND(ISNUMBER($G19), ISNUMBER($H19), $G19<=Helper!S$2, $H19>=Helper!S$1), 1, "") | ... AL19: =IF(AND(ISNUMBER($G19), ISNUMBER($H19), $G19<=Helper!AM$2, $H19>=Helper!AM$1), 1, "")
B20: D4 | C20: Increment 4 | D20: MC | E20: Increment 4 Deliverables | F20: D3 | G20: 46281 | H20: 46310 | I20: Planned | J20: 0 | K20: =IF(AND(ISNUMBER($G20), ISNUMBER($H20), $G20<=Helper!L$2, $H20>=Helper!L$1), 1, "") | L20: =IF(AND(ISNUMBER($G20), ISNUMBER($H20), $G20<=Helper!M$2, $H20>=Helper!M$1), 1, "") | M20: =IF(AND(ISNUMBER($G20), ISNUMBER($H20), $G20<=Helper!N$2, $H20>=Helper!N$1), 1, "") | N20: =IF(AND(ISNUMBER($G20), ISNUMBER($H20), $G20<=Helper!O$2, $H20>=Helper!O$1), 1, "") | O20: =IF(AND(ISNUMBER($G20), ISNUMBER($H20), $G20<=Helper!P$2, $H20>=Helper!P$1), 1, "") | P20: =IF(AND(ISNUMBER($G20), ISNUMBER($H20), $G20<=Helper!Q$2, $H20>=Helper!Q$1), 1, "") | Q20: =IF(AND(ISNUMBER($G20), ISNUMBER($H20), $G20<=Helper!R$2, $H20>=Helper!R$1), 1, "") | R20: =IF(AND(ISNUMBER($G20), ISNUMBER($H20), $G20<=Helper!S$2, $H20>=Helper!S$1), 1, "") | ... AL20: =IF(AND(ISNUMBER($G20), ISNUMBER($H20), $G20<=Helper!AM$2, $H20>=Helper!AM$1), 1, "")
A21: MILESTONES | K21: =IF(AND(ISNUMBER($G21), ISNUMBER($H21), $G21<=Helper!L$2, $H21>=Helper!L$1), 1, "") | L21: =IF(AND(ISNUMBER($G21), ISNUMBER($H21), $G21<=Helper!M$2, $H21>=Helper!M$1), 1, "") | M21: =IF(AND(ISNUMBER($G21), ISNUMBER($H21), $G21<=Helper!N$2, $H21>=Helper!N$1), 1, "") | N21: =IF(AND(ISNUMBER($G21), ISNUMBER($H21), $G21<=Helper!O$2, $H21>=Helper!O$1), 1, "") | O21: =IF(AND(ISNUMBER($G21), ISNUMBER($H21), $G21<=Helper!P$2, $H21>=Helper!P$1), 1, "") | P21: =IF(AND(ISNUMBER($G21), ISNUMBER($H21), $G21<=Helper!Q$2, $H21>=Helper!Q$1), 1, "") | Q21: =IF(AND(ISNUMBER($G21), ISNUMBER($H21), $G21<=Helper!R$2, $H21>=Helper!R$1), 1, "") | R21: =IF(AND(ISNUMBER($G21), ISNUMBER($H21), $G21<=Helper!S$2, $H21>=Helper!S$1), 1, "") | ... AL21: =IF(AND(ISNUMBER($G21), ISNUMBER($H21), $G21<=Helper!AM$2, $H21>=Helper!AM$1), 1, "")
B22: M1 | C22: Signed Schedule of Deliverables | D22: Both | G22: 46199 | N22: ◆
B23: M2 | C23: Chapter 2, Chapter 3 and Bibliography submitted | D23: JD | G23: 46206 | O23: ◆
B24: M3 | C24: Research Objectives / Statement of the Problem | D24: Both | G24: 46212 | P24: ◆
B25: M4 | C25: Chapter 4 Design and Methodology submitted | D25: MC | G25: 46213 | P25: ◆
B26: M5 | C26: Appendices (transmittal, instrument, SRS) and CV | D26: Both | G26: 46219 | Q26: ◆
B27: M6 | C27: Chapter 1 and Abstract submitted | D27: Both | G27: 46220 | Q27: ◆
B28: M7 | C28: Proposal Document Draft Ch. 1–4 with refs, appendices, CV | D28: Both | G28: 46226 | R28: ◆
B29: M8 | C29: Agreement Letter (with parent's signature) | D29: Both | G29: 46227 | R29: ◆
B30: M9 | C30: 3 copies of Thesis Proposal Document + sworn and recommendation letter | D30: Both | G30: 46230 | R30: ◆
B31: M10 | C31: **Thesis Proposal Defense** | D31: Both | G31: Mon–Wed 03–05-Aug-2026 | S31: ◆
B32: M11 | C32: Submission of Rubric 1, 2.1 and 2.2 | D32: Both | G32: 46244 | T32: ◆
B33: M12 | C33: Revised Thesis Document and Compliance Form | D33: Both | G33: 46248 | T33: ◆
B34: M13 | C34: Conference | D34: Both | G34: 46308
B35: M14 | C35: Hardbound Copy | D35: Both | G35: 46371
B36: M15 | C36: **Final Defense** | D36: Both | G36: 46384
A37: CLOSEOUT | K37: =IF(AND(ISNUMBER($G37), ISNUMBER($H37), $G37<=Helper!L$2, $H37>=Helper!L$1), 1, "") | L37: =IF(AND(ISNUMBER($G37), ISNUMBER($H37), $G37<=Helper!M$2, $H37>=Helper!M$1), 1, "") | M37: =IF(AND(ISNUMBER($G37), ISNUMBER($H37), $G37<=Helper!N$2, $H37>=Helper!N$1), 1, "") | N37: =IF(AND(ISNUMBER($G37), ISNUMBER($H37), $G37<=Helper!O$2, $H37>=Helper!O$1), 1, "") | O37: =IF(AND(ISNUMBER($G37), ISNUMBER($H37), $G37<=Helper!P$2, $H37>=Helper!P$1), 1, "") | P37: =IF(AND(ISNUMBER($G37), ISNUMBER($H37), $G37<=Helper!Q$2, $H37>=Helper!Q$1), 1, "") | Q37: =IF(AND(ISNUMBER($G37), ISNUMBER($H37), $G37<=Helper!R$2, $H37>=Helper!R$1), 1, "") | R37: =IF(AND(ISNUMBER($G37), ISNUMBER($H37), $G37<=Helper!S$2, $H37>=Helper!S$1), 1, "") | ... AL37: =IF(AND(ISNUMBER($G37), ISNUMBER($H37), $G37<=Helper!AM$2, $H37>=Helper!AM$1), 1, "")
B38: C1 | C38: Closeout Activities (Testing, Revision, Defense Prep) | D38: Both | E38: Final deliverables | F38: W10, D4 | G38: 46327 | H38: 46376 | I38: Planned | J38: 0 | K38: =IF(AND(ISNUMBER($G38), ISNUMBER($H38), $G38<=Helper!L$2, $H38>=Helper!L$1), 1, "") | L38: =IF(AND(ISNUMBER($G38), ISNUMBER($H38), $G38<=Helper!M$2, $H38>=Helper!M$1), 1, "") | M38: =IF(AND(ISNUMBER($G38), ISNUMBER($H38), $G38<=Helper!N$2, $H38>=Helper!N$1), 1, "") | N38: =IF(AND(ISNUMBER($G38), ISNUMBER($H38), $G38<=Helper!O$2, $H38>=Helper!O$1), 1, "") | O38: =IF(AND(ISNUMBER($G38), ISNUMBER($H38), $G38<=Helper!P$2, $H38>=Helper!P$1), 1, "") | P38: =IF(AND(ISNUMBER($G38), ISNUMBER($H38), $G38<=Helper!Q$2, $H38>=Helper!Q$1), 1, "") | Q38: =IF(AND(ISNUMBER($G38), ISNUMBER($H38), $G38<=Helper!R$2, $H38>=Helper!R$1), 1, "") | R38: =IF(AND(ISNUMBER($G38), ISNUMBER($H38), $G38<=Helper!S$2, $H38>=Helper!S$1), 1, "") | ... AL38: =IF(AND(ISNUMBER($G38), ISNUMBER($H38), $G38<=Helper!AM$2, $H38>=Helper!AM$1), 1, "")
B39: Completed
B40: In progress
...

Sheet Consultations
A1: Date | B1: Adviser | C1: Topic | D1: Action items | E1: Resolved?

Sheet Helper
L1: 46174 | M1: 46181 | N1: 46188 | O1: 46195 | P1: 46204 | Q1: 46211 | R1: 46218 | S1: 46225 | T1: 46235 | U1: 46242 | V1: 46249 | W1: 46256 | X1: 46266 | Y1: 46273 | Z1: 46280 | AA1: 46287 | AB1: 46296 | AC1: 46303 | AD1: 46310 | AE1: 46317 | AF1: 46327 | AG1: 46334 | AH1: 46341 | AI1: 46348 | AJ1: 46357 | AK1: 46364 | AL1: 46371 | AM1: 46378
L2: 46180 | M2: 46187 | N2: 46194 | O2: 46203 | P2: 46210 | Q2: 46217 | R2: 46224 | S2: 46234 | T2: 46241 | U2: 46248 | V2: 46255 | W2: 46265 | X2: 46272 | Y2: 46279 | Z2: 46286 | AA2: 46295 | AB2: 46302 | AC2: 46309 | AD2: 46316 | AE2: 46326 | AF2: 46333 | AG2: 46340 | AH2: 46347 | AI2: 46356 | AJ2: 46363 | AK2: 46370 | AL2: 46377 | AM2: 46387
